[2024-11-02T19:16:03.390+0000] {local_task_job_runner.py:123} INFO - ::group::Pre task execution logs
[2024-11-02T19:16:03.628+0000] {taskinstance.py:2612} INFO - Dependencies all met for dep_context=non-requeueable deps ti=<TaskInstance: car_price_prediction.pipeline scheduled__2022-06-16T15:00:00+00:00 [queued]>
[2024-11-02T19:16:03.645+0000] {taskinstance.py:2612} INFO - Dependencies all met for dep_context=requeueable deps ti=<TaskInstance: car_price_prediction.pipeline scheduled__2022-06-16T15:00:00+00:00 [queued]>
[2024-11-02T19:16:03.646+0000] {taskinstance.py:2865} INFO - Starting attempt 1 of 2
[2024-11-02T19:16:03.694+0000] {taskinstance.py:2888} INFO - Executing <Task(PythonOperator): pipeline> on 2022-06-16 15:00:00+00:00
[2024-11-02T19:16:03.709+0000] {warnings.py:112} WARNING - /home/***/.local/lib/python3.12/site-packages/***/task/task_runner/standard_task_runner.py:70: DeprecationWarning: This process (pid=5501) is multi-threaded, use of fork() may lead to deadlocks in the child.
  pid = os.fork()

[2024-11-02T19:16:03.711+0000] {standard_task_runner.py:72} INFO - Started process 5657 to run task
[2024-11-02T19:16:03.712+0000] {standard_task_runner.py:104} INFO - Running: ['***', 'tasks', 'run', 'car_price_prediction', 'pipeline', 'scheduled__2022-06-16T15:00:00+00:00', '--job-id', '18', '--raw', '--subdir', 'DAGS_FOLDER/hw_dag.py', '--cfg-path', '/tmp/tmp365zo8rd']
[2024-11-02T19:16:03.714+0000] {standard_task_runner.py:105} INFO - Job 18: Subtask pipeline
[2024-11-02T19:16:04.185+0000] {task_command.py:467} INFO - Running <TaskInstance: car_price_prediction.pipeline scheduled__2022-06-16T15:00:00+00:00 [running]> on host eb9dd9e7d0cb
[2024-11-02T19:16:04.800+0000] {taskinstance.py:3131} INFO - Exporting env vars: AIRFLOW_CTX_DAG_OWNER='***' AIRFLOW_CTX_DAG_ID='car_price_prediction' AIRFLOW_CTX_TASK_ID='pipeline' AIRFLOW_CTX_EXECUTION_DATE='2022-06-16T15:00:00+00:00' AIRFLOW_CTX_TRY_NUMBER='1' AIRFLOW_CTX_DAG_RUN_ID='scheduled__2022-06-16T15:00:00+00:00'
[2024-11-02T19:16:04.803+0000] {logging_mixin.py:190} INFO - Task instance is in running state
[2024-11-02T19:16:04.808+0000] {logging_mixin.py:190} INFO -  Previous state of the Task instance: queued
[2024-11-02T19:16:04.809+0000] {logging_mixin.py:190} INFO - Current task name:pipeline state:running start_date:2024-11-02 19:16:03.629364+00:00
[2024-11-02T19:16:04.810+0000] {logging_mixin.py:190} INFO - Dag name:car_price_prediction and current dag run status:running
[2024-11-02T19:16:04.811+0000] {taskinstance.py:731} INFO - ::endgroup::
[2024-11-02T19:16:50.044+0000] {job.py:229} INFO - Heartbeat recovered after 47.65 seconds
[2024-11-02T19:16:53.866+0000] {pipeline.py:116} INFO - model: LogisticRegression, acc_mean: 0.7591, acc_std: 0.0075
[2024-11-02T19:17:43.553+0000] {job.py:229} INFO - Heartbeat recovered after 43.22 seconds
[2024-11-02T19:18:05.391+0000] {job.py:229} INFO - Heartbeat recovered after 16.67 seconds
[2024-11-02T19:18:36.896+0000] {job.py:239} ERROR - Job heartbeat failed with error
Traceback (most recent call last):
  File "/home/airflow/.local/lib/python3.12/site-packages/sqlalchemy/engine/base.py", line 3371, in _wrap_pool_connect
    return fn()
           ^^^^
  File "/home/airflow/.local/lib/python3.12/site-packages/sqlalchemy/pool/base.py", line 327, in connect
    return _ConnectionFairy._checkout(self)
           ^^^^^^^^^^^^^^^^^^^^^^^^^^^^^^^^
  File "/home/airflow/.local/lib/python3.12/site-packages/sqlalchemy/pool/base.py", line 894, in _checkout
    fairy = _ConnectionRecord.checkout(pool)
            ^^^^^^^^^^^^^^^^^^^^^^^^^^^^^^^^
  File "/home/airflow/.local/lib/python3.12/site-packages/sqlalchemy/pool/base.py", line 493, in checkout
    rec = pool._do_get()
          ^^^^^^^^^^^^^^
  File "/home/airflow/.local/lib/python3.12/site-packages/sqlalchemy/pool/impl.py", line 256, in _do_get
    return self._create_connection()
           ^^^^^^^^^^^^^^^^^^^^^^^^^
  File "/home/airflow/.local/lib/python3.12/site-packages/sqlalchemy/pool/base.py", line 273, in _create_connection
    return _ConnectionRecord(self)
           ^^^^^^^^^^^^^^^^^^^^^^^
  File "/home/airflow/.local/lib/python3.12/site-packages/sqlalchemy/pool/base.py", line 388, in __init__
    self.__connect()
  File "/home/airflow/.local/lib/python3.12/site-packages/sqlalchemy/pool/base.py", line 690, in __connect
    with util.safe_reraise():
         ^^^^^^^^^^^^^^^^^^^
  File "/home/airflow/.local/lib/python3.12/site-packages/sqlalchemy/util/langhelpers.py", line 70, in __exit__
    compat.raise_(
  File "/home/airflow/.local/lib/python3.12/site-packages/sqlalchemy/util/compat.py", line 211, in raise_
    raise exception
  File "/home/airflow/.local/lib/python3.12/site-packages/sqlalchemy/pool/base.py", line 686, in __connect
    self.dbapi_connection = connection = pool._invoke_creator(self)
                                         ^^^^^^^^^^^^^^^^^^^^^^^^^^
  File "/home/airflow/.local/lib/python3.12/site-packages/sqlalchemy/engine/create.py", line 574, in connect
    return dialect.connect(*cargs, **cparams)
           ^^^^^^^^^^^^^^^^^^^^^^^^^^^^^^^^^^
  File "/home/airflow/.local/lib/python3.12/site-packages/sqlalchemy/engine/default.py", line 598, in connect
    return self.dbapi.connect(*cargs, **cparams)
           ^^^^^^^^^^^^^^^^^^^^^^^^^^^^^^^^^^^^^
  File "/home/airflow/.local/lib/python3.12/site-packages/psycopg2/__init__.py", line 122, in connect
    conn = _connect(dsn, connection_factory=connection_factory, **kwasync)
           ^^^^^^^^^^^^^^^^^^^^^^^^^^^^^^^^^^^^^^^^^^^^^^^^^^^^^^^^^^^^^^^
psycopg2.OperationalError: could not translate host name "postgres" to address: Temporary failure in name resolution


The above exception was the direct cause of the following exception:

Traceback (most recent call last):
  File "/home/airflow/.local/lib/python3.12/site-packages/airflow/jobs/job.py", line 233, in heartbeat
    heartbeat_callback(session)
  File "/home/airflow/.local/lib/python3.12/site-packages/airflow/utils/session.py", line 94, in wrapper
    return func(*args, **kwargs)
           ^^^^^^^^^^^^^^^^^^^^^
  File "/home/airflow/.local/lib/python3.12/site-packages/airflow/jobs/local_task_job_runner.py", line 284, in heartbeat_callback
    self.task_instance.refresh_from_db()
  File "/home/airflow/.local/lib/python3.12/site-packages/airflow/utils/session.py", line 97, in wrapper
    return func(*args, session=session, **kwargs)
           ^^^^^^^^^^^^^^^^^^^^^^^^^^^^^^^^^^^^^^
  File "/home/airflow/.local/lib/python3.12/site-packages/airflow/models/taskinstance.py", line 2358, in refresh_from_db
    _refresh_from_db(task_instance=self, session=session, lock_for_update=lock_for_update)
  File "/home/airflow/.local/lib/python3.12/site-packages/airflow/models/taskinstance.py", line 872, in _refresh_from_db
    ti = TaskInstance.get_task_instance(
         ^^^^^^^^^^^^^^^^^^^^^^^^^^^^^^^
  File "/home/airflow/.local/lib/python3.12/site-packages/airflow/api_internal/internal_api_call.py", line 139, in wrapper
    return func(*args, **kwargs)
           ^^^^^^^^^^^^^^^^^^^^^
  File "/home/airflow/.local/lib/python3.12/site-packages/airflow/utils/session.py", line 94, in wrapper
    return func(*args, **kwargs)
           ^^^^^^^^^^^^^^^^^^^^^
  File "/home/airflow/.local/lib/python3.12/site-packages/airflow/models/taskinstance.py", line 2344, in get_task_instance
    return query.one_or_none()
           ^^^^^^^^^^^^^^^^^^^
  File "/home/airflow/.local/lib/python3.12/site-packages/sqlalchemy/orm/query.py", line 2850, in one_or_none
    return self._iter().one_or_none()
           ^^^^^^^^^^^^
  File "/home/airflow/.local/lib/python3.12/site-packages/sqlalchemy/orm/query.py", line 2916, in _iter
    result = self.session.execute(
             ^^^^^^^^^^^^^^^^^^^^^
  File "/home/airflow/.local/lib/python3.12/site-packages/sqlalchemy/orm/session.py", line 1716, in execute
    conn = self._connection_for_bind(bind)
           ^^^^^^^^^^^^^^^^^^^^^^^^^^^^^^^
  File "/home/airflow/.local/lib/python3.12/site-packages/sqlalchemy/orm/session.py", line 1555, in _connection_for_bind
    return self._transaction._connection_for_bind(
           ^^^^^^^^^^^^^^^^^^^^^^^^^^^^^^^^^^^^^^^
  File "/home/airflow/.local/lib/python3.12/site-packages/sqlalchemy/orm/session.py", line 750, in _connection_for_bind
    conn = bind.connect()
           ^^^^^^^^^^^^^^
  File "/home/airflow/.local/lib/python3.12/site-packages/sqlalchemy/future/engine.py", line 412, in connect
    return super(Engine, self).connect()
           ^^^^^^^^^^^^^^^^^^^^^^^^^^^^^
  File "/home/airflow/.local/lib/python3.12/site-packages/sqlalchemy/engine/base.py", line 3325, in connect
    return self._connection_cls(self, close_with_result=close_with_result)
           ^^^^^^^^^^^^^^^^^^^^^^^^^^^^^^^^^^^^^^^^^^^^^^^^^^^^^^^^^^^^^^^
  File "/home/airflow/.local/lib/python3.12/site-packages/sqlalchemy/engine/base.py", line 96, in __init__
    else engine.raw_connection()
         ^^^^^^^^^^^^^^^^^^^^^^^
  File "/home/airflow/.local/lib/python3.12/site-packages/sqlalchemy/engine/base.py", line 3404, in raw_connection
    return self._wrap_pool_connect(self.pool.connect, _connection)
           ^^^^^^^^^^^^^^^^^^^^^^^^^^^^^^^^^^^^^^^^^^^^^^^^^^^^^^^
  File "/home/airflow/.local/lib/python3.12/site-packages/sqlalchemy/engine/base.py", line 3374, in _wrap_pool_connect
    Connection._handle_dbapi_exception_noconnection(
  File "/home/airflow/.local/lib/python3.12/site-packages/sqlalchemy/engine/base.py", line 2208, in _handle_dbapi_exception_noconnection
    util.raise_(
  File "/home/airflow/.local/lib/python3.12/site-packages/sqlalchemy/util/compat.py", line 211, in raise_
    raise exception
  File "/home/airflow/.local/lib/python3.12/site-packages/sqlalchemy/engine/base.py", line 3371, in _wrap_pool_connect
    return fn()
           ^^^^
  File "/home/airflow/.local/lib/python3.12/site-packages/sqlalchemy/pool/base.py", line 327, in connect
    return _ConnectionFairy._checkout(self)
           ^^^^^^^^^^^^^^^^^^^^^^^^^^^^^^^^
  File "/home/airflow/.local/lib/python3.12/site-packages/sqlalchemy/pool/base.py", line 894, in _checkout
    fairy = _ConnectionRecord.checkout(pool)
            ^^^^^^^^^^^^^^^^^^^^^^^^^^^^^^^^
  File "/home/airflow/.local/lib/python3.12/site-packages/sqlalchemy/pool/base.py", line 493, in checkout
    rec = pool._do_get()
          ^^^^^^^^^^^^^^
  File "/home/airflow/.local/lib/python3.12/site-packages/sqlalchemy/pool/impl.py", line 256, in _do_get
    return self._create_connection()
           ^^^^^^^^^^^^^^^^^^^^^^^^^
  File "/home/airflow/.local/lib/python3.12/site-packages/sqlalchemy/pool/base.py", line 273, in _create_connection
    return _ConnectionRecord(self)
           ^^^^^^^^^^^^^^^^^^^^^^^
  File "/home/airflow/.local/lib/python3.12/site-packages/sqlalchemy/pool/base.py", line 388, in __init__
    self.__connect()
  File "/home/airflow/.local/lib/python3.12/site-packages/sqlalchemy/pool/base.py", line 690, in __connect
    with util.safe_reraise():
         ^^^^^^^^^^^^^^^^^^^
  File "/home/airflow/.local/lib/python3.12/site-packages/sqlalchemy/util/langhelpers.py", line 70, in __exit__
    compat.raise_(
  File "/home/airflow/.local/lib/python3.12/site-packages/sqlalchemy/util/compat.py", line 211, in raise_
    raise exception
  File "/home/airflow/.local/lib/python3.12/site-packages/sqlalchemy/pool/base.py", line 686, in __connect
    self.dbapi_connection = connection = pool._invoke_creator(self)
                                         ^^^^^^^^^^^^^^^^^^^^^^^^^^
  File "/home/airflow/.local/lib/python3.12/site-packages/sqlalchemy/engine/create.py", line 574, in connect
    return dialect.connect(*cargs, **cparams)
           ^^^^^^^^^^^^^^^^^^^^^^^^^^^^^^^^^^
  File "/home/airflow/.local/lib/python3.12/site-packages/sqlalchemy/engine/default.py", line 598, in connect
    return self.dbapi.connect(*cargs, **cparams)
           ^^^^^^^^^^^^^^^^^^^^^^^^^^^^^^^^^^^^^
  File "/home/airflow/.local/lib/python3.12/site-packages/psycopg2/__init__.py", line 122, in connect
    conn = _connect(dsn, connection_factory=connection_factory, **kwasync)
           ^^^^^^^^^^^^^^^^^^^^^^^^^^^^^^^^^^^^^^^^^^^^^^^^^^^^^^^^^^^^^^^
sqlalchemy.exc.OperationalError: (psycopg2.OperationalError) could not translate host name "postgres" to address: Temporary failure in name resolution

(Background on this error at: https://sqlalche.me/e/14/e3q8)
[2024-11-02T19:19:46.431+0000] {job.py:254} ERROR - Job heartbeat failed with error. Scheduler is in unhealthy state
[2024-11-02T19:19:51.723+0000] {job.py:229} INFO - Heartbeat recovered after 106.39 seconds
[2024-11-02T19:21:20.989+0000] {pipeline.py:116} INFO - model: RandomForestClassifier, acc_mean: 0.7775, acc_std: 0.0029
[2024-11-02T19:24:00.554+0000] {job.py:229} INFO - Heartbeat recovered after 103.09 seconds
[2024-11-02T19:24:26.958+0000] {pipeline.py:116} INFO - model: SVC, acc_mean: 0.7871, acc_std: 0.0042
[2024-11-02T19:24:26.967+0000] {pipeline.py:121} INFO - best model: SVC, accuracy: 0.7871
[2024-11-02T19:25:24.481+0000] {job.py:229} INFO - Heartbeat recovered after 52.14 seconds
[2024-11-02T19:25:33.642+0000] {pipeline.py:129} INFO - Model is saved as /opt/***/data/models/cars_pipe_202411021925.pkl
[2024-11-02T19:25:33.690+0000] {python.py:240} INFO - Done. Returned value was: None
[2024-11-02T19:25:33.740+0000] {taskinstance.py:340} INFO - ::group::Post task execution logs
[2024-11-02T19:25:33.742+0000] {taskinstance.py:352} INFO - Marking task as SUCCESS. dag_id=car_price_prediction, task_id=pipeline, run_id=scheduled__2022-06-16T15:00:00+00:00, execution_date=20220616T150000, start_date=20241102T191603, end_date=20241102T192533
[2024-11-02T19:25:34.146+0000] {logging_mixin.py:190} INFO - Task instance in success state
[2024-11-02T19:25:34.147+0000] {logging_mixin.py:190} INFO -  Previous state of the Task instance: running
[2024-11-02T19:25:34.149+0000] {logging_mixin.py:190} INFO - Dag name:car_price_prediction queued_at:2024-11-02 19:15:41.997931+00:00
[2024-11-02T19:25:34.150+0000] {logging_mixin.py:190} INFO - Task hostname:eb9dd9e7d0cb operator:PythonOperator
[2024-11-02T19:25:34.274+0000] {local_task_job_runner.py:266} INFO - Task exited with return code 0
[2024-11-02T19:25:34.345+0000] {taskinstance.py:3900} INFO - 1 downstream tasks scheduled from follow-on schedule check
[2024-11-02T19:25:34.352+0000] {local_task_job_runner.py:245} INFO - ::endgroup::
